<?xml version="1.0" ?>
<robot name="self_driving_car"
  xmlns:xacro="http://ros.org/wiki/xacro">
  <xacro:include filename="$(find turtlebot3_description)/urdf/common_properties.urdf"/>
  <link name="base_link">
  <joint name="base_joint" type="fixed">
    <parent link="base_link"/>
    <child link="body"/>
    <origin xyz="0.0 0.0 0.010" rpy="0 0 0"/>
  </joint>

  <link name="body"/>
    <visual>
      <origin xyz="-0.032 0 0.0" rpy="0 0 0"/>
      <geometry>
        <mesh filename="package://self_driving_car_description/meshes/car_body.stl" scale="0.001 0.001 0.001"/>
      </geometry>
      <material name="light_black"/>
    </visual>

    <collision>
      <origin xyz="-0.032 0 0.070" rpy="0 0 0"/>
      <geometry>
        <box size="0.140 0.140 0.143"/>
      </geometry>
    </collision>

    <inertial>
      <origin xyz="0 0 0" rpy="0 0 0"/>
      <mass value="8.2573504e-01"/>
      <inertia ixx="2.2124416e-03" ixy="-1.2294101e-05" ixz="3.4938785e-05" iyy="2.1193702e-03" iyz="-5.0120904e-06" izz="2.0064271e-03" />
    </inertial>
  </link>

  <joint name="front_left_joint" type="continuous">
    <parent link="body"/>
    <child link="front_left_wheel"/>
    <origin xyz="0.0 0.08 0.023" rpy="-1.57 0 0"/>
    <axis xyz="1 0 0"/>
  </joint>

  <link name="front_left_wheel">
    <visual>
      <origin xyz="0 0 0" rpy="1.57 0 0"/>
      <geometry>
        <cylinder length="0.5" radius="1"/>
      </geometry>
      <material name="black"/>
    </visual>

    <collision>
      <origin xyz="0 0 0" rpy="0 0 0"/>
      <geometry>
        <cylinder length="0.018" radius="0.033"/>
      </geometry>
    </collision>

    <inertial>
      <origin xyz="0 0 0" />
      <mass value="2.8498940e-02" />
      <inertia ixx="1.1175580e-05" ixy="-4.2369783e-11" ixz="-5.9381719e-09" iyy="1.1192413e-05" iyz="-1.4400107e-11" izz="2.0712558e-05" />
    </inertial>
  </link>
  
  <joint name="front_right_joint" type="continuous">
    <parent link="body"/>
    <child link="front_right_wheel"/>
    <origin xyz="1 0.08 0.023" rpy="-1.57 0 0"/>
    <axis xyz="1 0 0"/>
  </joint>

  <link name="front_right_wheel">
    <visual>
      <origin xyz="1 0 0" rpy="1.57 0 0"/>
      <geometry>
        <cylinder length="0.5" radius="1"/>
      </geometry>
      <material name="black"/>
    </visual>

    <collision>
      <origin xyz="0 0 0" rpy="0 0 0"/>
      <geometry>
        <cylinder length="0.018" radius="0.033"/>
      </geometry>
    </collision>

    <inertial>
      <origin xyz="0 0 0" />
      <mass value="2.8498940e-02" />
      <inertia ixx="1.1175580e-05" ixy="-4.2369783e-11" ixz="-5.9381719e-09" iyy="1.1192413e-05" iyz="-1.4400107e-11" izz="2.0712558e-05" />
    </inertial>
  </link> 

  <joint name="sensor_joint" type="fixed">
    <parent link="body"/>
    <child link="sensor"/>
    <origin xyz="-0.032 0 0.172" rpy="0 0 0"/>
  </joint>
  
  <link name="sensor">
    <visual>
      <origin xyz="0 0 0.0" rpy="0 0 0"/>
      <geometry>
         <box size="0.5 0.5 0.5"/>
      </geometry>
      <material name="dark"/>
    </visual>
    <collision>
      <origin xyz="0.015 0 -0.0065" rpy="0 0 0"/>
      <geometry>
         <box size="0.5 0.5 0.5"/>
      </geometry>
    </collision>
    <inertial>
      <mass value="0.114" />
      <origin xyz="0 0 0" />
      <inertia ixx="0.001" ixy="0.0" ixz="0.0" iyy="0.001" iyz="0.0" izz="0.001" />
    </inertial>
  </link>


	<unity reference="base_link">
    	<component name="CarController"/>
	</unity>
	<unity reference="sensor">
		<component name="Sensor"/>
	</unity>
</robot>